# El bloque try generará una excepción,
# porque x no está definida:
try:
    print(x)
except:
    print("Ocurrió una excepción")
